Workbook

Sheet Коди
A1: Дисципліна | B1: ПІБ викладача | C1: Код від клас рум | D1: Посилання на пару
A2: Фізичне виховання | B2: Тарнавський А.М. | C2: jpfvrsu7 | D2: https://meet.google.com/wsj-kptu-mdc
A3: Архітектура комп'ютерів | B3: Науменко П.В. | C3: 3po3mkph | D3: https://meet.google.com/der-ikqk-ttx?authuser=0&pli=1
A4: Комп`ютерна логіка | B4: Науменко П.В. | C4: jpatsiyd | D4: https://meet.google.com/qhf-gkjm-ssj?authuser=0
A5: Основи програмної інженерії | B5: Науменко П.В. | C5: kchbw2ur | D5: https://meet.google.com/ptm-sczv-xwz?authuser=0&pli=1
A6: Технічне обслуговування ЕОМ | B6: Науменко П.В. | C6: pdcuo6d2 | D6: https://meet.google.com/vck-hqkh-zqm?authuser=0&pli=1
A7: Дискретна математика | B7: Казмірчук О.І. | C7: nekmgfmh | D7: https://meet.google.com/ubd-wwuj-fjs
A8: Теорія ймовірності та математична статистика | B8: Казмірчук О. І. | C8: 63yhcccr | D8: https://meet.google.com/uwa-vwpb-yjw
A9: Системне програмування | B9: Порохня І.М. | C9: ty73cgt | D9: https://meet.google.com/bnq-tajj-tjd
A10: Огранізація баз даних | B10: Порохня І.М. | C10: rhtadrh6 | D10: https://meet.google.com/zqh-wocn-fxp
A11: Компʼютерні мережі | B11: Коваль А.М | D11: https://meet.google.com/bjb-mpgg-jzq
A12: Соціологія | B12: Лбченко Л.В | C12: jbn7j2h3 | D12: https://meet.google.com/gfh-jjjy-qip
A14: Синхронно

Sheet Звітність 1 семестр
B1: Дисципліна | D1: Дискретна математика | E1: Архітектура комп'ютерів | F1: Комп'ютерна логіка | G1: Комп'ютерні мережі | H1: Організація баз даних | I1: Основи програмної інженерії | J1: Системне програмування | K1: Технічне обслуговування ЕОМ | L1: Фізичне виховання | M1: Технологічна практика | N1: середній бал | O1: додаткові бали | P1: Рейтинговий бал
B2: екзамен/залік/ КП/ КР/ | D2: залік | E2: екзамен | F2: екзамен | G2: семестрова | H2: семестрова | J2: екзамен | K2: семестрова | L2: залік | M2: залік
A3: № | B3: ПІБ студента
A4: 1 | B4: Гриценко Денис Сергійович | C4: к | D4: ='Дискретна математика'!AE4 -> н/а | E4: ='Архітектура компютерів'!AF4 -> н/д | F4: ='Компютерна логіка'!AU4 -> н/д | G4: ='Компютерні мережі'!AE4 -> н/а | H4: ='Організація баз даних'!AE4 -> 3 | I4: ='Основи програмної інженерії'!AE4 -> н/а | J4: ='Системне програмування'!R4 -> н/д | K4: ='Технічне обслуговування ЕОМ'!AE4 -> н/а | L4: ='Фізичне виховання'!R4 -> 3.5 | M4: 3 | N4: =sum(D4:M4)/10 -> 0.95 | P4: =N4*0.9+O4*0.1 -> 0.855 | Q4: відрахований наказ №17-с/к від 27.02.2026
A5: 2 | B5: Гришков Едуард Сергійович | C5: к | D5: ='Дискретна математика'!AE5 -> н/а | E5: 3 | F5: ='Компютерна логіка'!AU5 -> н/д | G5: ='Компютерні мережі'!AE5 -> н/а | H5: ='Організація баз даних'!AE5 -> н/а | I5: ='Основи програмної інженерії'!AE5 -> н/а | J5: ='Системне програмування'!R5 -> н/д | K5: ='Технічне обслуговування ЕОМ'!AE5 -> н/а | L5: ='Фізичне виховання'!R5 -> н/а | M5: 2 | N5: =sum(D5:M5)/10 -> 0.5 | P5: =N5*0.9+O5*0.1 -> 0.45 | Q5: відрахований наказ №29-с/к від 27.03.26
A6: 3 | B6: Дворник Іван Миколайович | C6: УБД | D6: ='Дискретна математика'!AE6 -> 3 | E6: ='Архітектура компютерів'!AF6 -> 4 | F6: ='Компютерна логіка'!AU6 -> 4 | G6: ='Компютерні мережі'!AE6 -> 3 | H6: ='Організація баз даних'!AE6 -> 3 | I6: ='Основи програмної інженерії'!AE6 -> 3 | J6: ='Системне програмування'!R6 -> 4 | K6: ='Технічне обслуговування ЕОМ'!AE6 -> н/а | L6: ='Фізичне виховання'!R6 -> 3 | M6: 5 | N6: =sum(D6:M6)/10 -> 3.2 | P6: =N6*0.9+O6*0.1 -> 2.88
A7: 4 | B7: Демченко Максим Сергійович | C7: к | D7: ='Дискретна математика'!AE7 -> н/а | E7: ='Архітектура компютерів'!AF7 -> н/д | F7: ='Компютерна логіка'!AU7 -> н/д | G7: ='Компютерні мережі'!AE7 -> н/а | H7: ='Організація баз даних'!AE7 -> н/а | I7: ='Основи програмної інженерії'!AE7 -> н/а | J7: ='Системне програмування'!R7 -> н/д | K7: ='Технічне обслуговування ЕОМ'!AE7 -> н/а | L7: ='Фізичне виховання'!R7 -> н/а | M7: н/а | N7: =sum(D7:M7)/10 -> 0 | P7: =N7*0.9+O7*0.1 -> 0 | Q7: відрахований наказ №15-с/к від 18.02.2026
A8: 5 | B8: Івахненко Олександр Олександрович | D8: ='Дискретна математика'!AE8 -> н/а | E8: ='Архітектура компютерів'!AF8 -> н/д | F8: ='Компютерна логіка'!AU8 -> н/д | G8: ='Компютерні мережі'!AE8 -> н/а | H8: ='Організація баз даних'!AE8 -> н/а | I8: ='Основи програмної інженерії'!AE8 -> н/а | J8: ='Системне програмування'!R8 -> н/д | K8: ='Технічне обслуговування ЕОМ'!AE8 -> н/а | L8: ='Фізичне виховання'!R8 -> н/а | M8: 2 | N8: =sum(D8:M8)/10 -> 0.2 | P8: =N8*0.9+O8*0.1 -> 0.18 | Q8: академічна відпустка наказ №14-с/к від 16.02.26
A9: 6 | B9: Ішков Леонід Вікторович | C9: ВПО | D9: ='Дискретна математика'!AE9 -> 4 | E9: ='Архітектура компютерів'!AF9 -> 5 | F9: ='Компютерна логіка'!AU9 -> 5 | G9: ='Компютерні мережі'!AE9 -> 5 | H9: ='Організація баз даних'!AE9 -> 5 | I9: ='Основи програмної інженерії'!AE9 -> 5 | J9: ='Системне програмування'!R9 -> 5 | K9: ='Технічне обслуговування ЕОМ'!AE9 -> 4 | L9: ='Фізичне виховання'!R9 -> 4.6 | M9: 5 | N9: =sum(D9:M9)/10 -> 4.76 | P9: =N9*0.9+O9*0.1 -> 4.284
A10: 7 | B10: Каратаєв Данііл Сергійович | C10: к | D10: ='Дискретна математика'!AE10 -> 3 | E10: 3 | F10: ='Компютерна логіка'!AU10 -> 4 | G10: ='Компютерні мережі'!AE10 -> 3 | H10: ='Організація баз даних'!AE10 -> 3 | I10: 4 | J10: ='Системне програмування'!R10 -> 4 | K10: 3 | L10: ='Фізичне виховання'!R10 -> 3 | M10: 4 | N10: =sum(D10:M10)/10 -> 3.4 | P10: =N10*0.9+O10*0.1 -> 3.06
A11: 8 | B11: Кисляков Дмитро Олександрович | D11: ='Дискретна математика'!AE11 -> 4 | E11: ='Архітектура компютерів'!AF11 -> 5 | F11: ='Компютерна логіка'!AU11 -> 4 | G11: ='Компютерні мережі'!AE11 -> 5 | H11: ='Організація баз даних'!AE11 -> 5 | I11: 4 | J11: ='Системне програмування'!R11 -> 5 | K11: ='Технічне обслуговування ЕОМ'!AE11 -> 4 | L11: ='Фізичне виховання'!R11 -> 4.625 | M11: 5 | N11: =sum(D11:M11)/10 -> 4.5625 | P11: =N11*0.9+O11*0.1 -> 4.10625
A12: 9 | B12: Ковальчук Арсеній Борисович | C12: к | D12: ='Дискретна математика'!AE12 -> н/а | E12: ='Архітектура компютерів'!AF12 -> н/д | F12: ='Компютерна логіка'!AU12 -> н/д | G12: ='Компютерні мережі'!AE12 -> н/а | H12: ='Організація баз даних'!AE12 -> н/а | I12: ='Основи програмної інженерії'!AE12 -> н/а | J12: ='Системне програмування'!R12 -> н/д | K12: ='Технічне обслуговування ЕОМ'!AE12 -> н/а | L12: ='Фізичне виховання'!R12 -> н/а | M12: 2 | N12: =sum(D12:M12)/10 -> 0.2 | P12: =N12*0.9+O12*0.1 -> 0.18 | Q12: відрахований наказ №17-с/к від 27.02.2026
A13: 10 | B13: Кутєхов Назарій Олександрович | C13: к | D13: ='Дискретна математика'!AE13 -> н/а | E13: 3 | F13: 3 | G13: ='Компютерні мережі'!AE13 -> н/а | H13: ='Організація баз даних'!AE13 -> н/а | I13: 3 | J13: ='Системне програмування'!R13 -> н/д | K13: 3 | L13: 3 | M13: 2 | N13: =sum(D13:M13)/10 -> 1.7 | P13: =N13*0.9+O13*0.1 -> 1.53
A14: 11 | B14: Малюк Нікіта Сергійович | C14: УБД | D14: ='Дискретна математика'!AE14 -> 3 | E14: ='Архітектура компютерів'!AF14 -> 4 | F14: ='Компютерна логіка'!AU14 -> 3 | G14: ='Компютерні мережі'!AE14 -> 3 | H14: ='Організація баз даних'!AE14 -> 4 | I14: ='Основи програмної інженерії'!AE14 -> 3 | J14: ='Системне програмування'!R14 -> 3 | K14: ='Технічне обслуговування ЕОМ'!AE14 -> н/а | L14: ='Фізичне виховання'!R14 -> 4.5 | M14: 4 | N14: =sum(D14:M14)/10 -> 3.15 | P14: =N14*0.9+O14*0.1 -> 2.835
A15: 12 | B15: Мезенцев Кирило Анатолійович | C15: к | D15: ='Дискретна математика'!AE15 -> н/а | E15: ='Архітектура компютерів'!AF15 -> н/д | F15: ='Компютерна логіка'!AU15 -> н/д | G15: ='Компютерні мережі'!AE15 -> н/а | H15: ='Організація баз даних'!AE15 -> н/а | I15: ='Основи програмної інженерії'!AE15 -> н/а | J15: ='Системне програмування'!R15 -> н/д | K15: ='Технічне обслуговування ЕОМ'!AE15 -> н/а | L15: ='Фізичне виховання'!R15 -> н/а | M15: 2 | N15: =sum(D15:M15)/10 -> 0.2 | P15: =N15*0.9+O15*0.1 -> 0.18 | Q15: відрахований наказ №18-с/к від 04.03.26
A16: 13 | B16: Надіров Расім Аріфович | C16: УБД | D16: ='Дискретна математика'!AE16 -> н/а | E16: ='Архітектура компютерів'!AF16 -> н/д | F16: ='Компютерна логіка'!AU16 -> н/д | G16: ='Компютерні мережі'!AE16 -> н/а | H16: ='Організація баз даних'!AE16 -> н/а | I16: ='Основи програмної інженерії'!AE16 -> н/а | J16: ='Системне програмування'!R16 -> н/д | K16: ='Технічне обслуговування ЕОМ'!AE16 -> н/а | L16: ='Фізичне виховання'!R16 -> н/а | M16: 3 | N16: =sum(D16:M16)/10 -> 0.3 | P16: =N16*0.9+O16*0.1 -> 0.27 | Q16: академічна відпустка наказ №16-с/к від 25.02.26
A17: 14 | B17: Онищенко Ярослав Віталійович | C17: к | D17: ='Дискретна математика'!AE17 -> н/а | E17: н/а | F17: ='Компютерна логіка'!AU17 -> н/д | G17: ='Компютерні мережі'!AE17 -> н/а | H17: ='Організація баз даних'!AE17 -> н/а | I17: ='Основи програмної інженерії'!AE17 -> н/а | J17: ='Системне програмування'!R17 -> н/д | K17: ='Технічне обслуговування ЕОМ'!AE17 -> н/а | L17: ='Фізичне виховання'!R17 -> н/а | M17: н/а | N17: =sum(D17:M17)/10 -> 0 | P17: =N17*0.9+O17*0.1 -> 0 | Q17: відрахований наказ №17-с/к від 27.02.2026
A18: 15 | B18: Павлюк Дмитро Ігорович | C18: к | D18: ='Дискретна математика'!AE18 -> н/а | E18: ='Архітектура компютерів'!AF18 -> н/д | F18: ='Компютерна логіка'!AU18 -> н/д | G18: ='Компютерні мережі'!AE18 -> н/а | H18: ='Організація баз даних'!AE18 -> н/а | I18: ='Основи програмної інженерії'!AE18 -> н/а | J18: ='Системне програмування'!R18 -> н/д | K18: ='Технічне обслуговування ЕОМ'!AE18 -> н/а | L18: 3 | M18: 3 | N18: =sum(D18:M18)/10 -> 0.6 | P18: =N18*0.9+O18*0.1 -> 0.54 | Q18: відрахований наказ №26-с/к від 17.03.2026
A19: 16 | B19: Плетій Андрій Анатолійович | C19: к | D19: ='Дискретна математика'!AE19 -> н/а | E19: ='Архітектура компютерів'!AF19 -> н/д | F19: ='Компютерна логіка'!AU19 -> н/д | G19: ='Компютерні мережі'!AE19 -> н/а | H19: ='Організація баз даних'!AE19 -> н/а | I19: ='Основи програмної інженерії'!AE19 -> н/а | J19: ='Системне програмування'!R19 -> н/д | K19: ='Технічне обслуговування ЕОМ'!AE19 -> н/а | L19: ='Фізичне виховання'!R19 -> н/а | M19: 2 | N19: =sum(D19:M19)/10 -> 0.2 | P19: =N19*0.9+O19*0.1 -> 0.18 | Q19: відрахований наказ №18-с/к від 04.03.26
A20: 17 | B20: Портаненко Гліб Олександрович | C20: ВПО | D20: ='Дискретна математика'!AE20 -> 3 | E20: ='Архітектура компютерів'!AF20 -> 3 | F20: ='Компютерна логіка'!AU20 -> 3 | G20: ='Компютерні мережі'!AE20 -> 3 | H20: ='Організація баз даних'!AE20 -> 3 | I20: 3 | J20: ='Системне програмування'!R20 -> н/д | K20: 3 | L20: 3 | M20: 3 | N20: =sum(D20:M20)/10 -> 2.7 | P20: =N20*0.9+O20*0.1 -> 2.43
A21: 18 | B21: Ткаченко Кирило Сергійович | C21: к | D21: ='Дискретна математика'!AE21 -> 2 | E21: ='Архітектура компютерів'!AF21 -> 3 | F21: ='Компютерна логіка'!AU21 -> 3 | G21: ='Компютерні мережі'!AE21 -> 4 | H21: ='Організація баз даних'!AE21 -> 4 | I21: 3 | J21: ='Системне програмування'!R21 -> 3 | K21: 3 | L21: ='Фізичне виховання'!R21 -> 3.75 | M21: 4 | N21: =sum(D21:M21)/10 -> 3.275 | P21: =N21*0.9+O21*0.1 -> 2.9475
A22: 19 | B22: Царюк Єгор Андрійович | C22: к | D22: ='Дискретна математика'!AE22 -> 3 | E22: ='Архітектура компютерів'!AF22 -> 3 | F22: ='Компютерна логіка'!AU22 -> 4 | G22: ='Компютерні мережі'!AE22 -> 4 | H22: ='Організація баз даних'!AE22 -> 5 | I22: ='Основи програмної інженерії'!AE22 -> 3 | J22: ='Системне програмування'!R22 -> 5 | K22: 3 | L22: ='Фізичне виховання'!R22 -> 3.8 | M22: 4 | N22: =sum(D22:M22)/10 -> 3.78 | P22: =N22*0.9+O22*0.1 -> 3.402

Sheet Звітність 2 семестр
B1: Дисципліна | D1: Економіка і планування виробництва | E1: Захист інформації та безпека ПК | F1: Комп'ютерні мережі | G1: Організація баз даних | H1: Основи програмної інженерії | I1: Теорія ймовірності та математична статистика | J1: Соціологія | K1: Технічне обслуговування ЕОМ | L1: Технічне обслуговування ЕОМ | M1: Переддипломна практика | N1: середній бал | O1: додаткові бали | P1: Рейтинговий бал
B2: екзамен/залік/ КП/ КР/ | D2: екзамен | E2: залік | F2: екзамен | H2: залік | I2: залік | J2: залік | K2: курсова | L2: екзамен | M2: залік
A3: № | B3: ПІБ студента
A4: 3 | B4: Дворник Іван Миколайович | D4: ='Економіка і планування виробниц'!AW6 -> 3 | E4: ='Захист інформації та безпека ПК'!U6 -> 3 | F4: ='Компютерні мережі'!CC6 -> 3 | G4: ='Організація баз даних'!BM6 -> 3 | H4: ='Основи програмної інженерії'!BM6 -> 4 | I4: ='Теорія ймовірності та математич'!AI6 -> 3 | J4: ='Соціологія'!AE6 -> 3 | K4: ='Технічне обслуговування ЕОМ'!BM6 -> 3 | L4: ='Технічне обслуговування ЕОМ'!BO6 -> 3 | M4: 5 | N4: =sum(D4:L4)/10 -> 2.8 | P4: =N4*0.9+O4*0.1 -> 2.52
A5: 6 | B5: Ішков Леонід Вікторович | D5: ='Економіка і планування виробниц'!AW9 -> 5 | E5: ='Захист інформації та безпека ПК'!U9 -> 5 | F5: ='Компютерні мережі'!CC9 -> 5 | G5: ='Організація баз даних'!BM9 -> 5 | H5: ='Основи програмної інженерії'!BM9 -> 5 | I5: ='Теорія ймовірності та математич'!AI9 -> 4 | J5: ='Соціологія'!AE9 -> 5 | K5: ='Технічне обслуговування ЕОМ'!BM9 -> 5 | L5: ='Технічне обслуговування ЕОМ'!BO9 -> 5 | M5: 5 | N5: =sum(D5:L5)/10 -> 4.4 | P5: =N5*0.9+O5*0.1 -> 3.96
A6: 7 | B6: Каратаєв Данііл Сергійович | D6: ='Економіка і планування виробниц'!AW10 -> 4 | E6: ='Захист інформації та безпека ПК'!U10 -> 3 | F6: ='Компютерні мережі'!CC10 -> 3 | G6: ='Організація баз даних'!BM10 -> 3 | H6: ='Основи програмної інженерії'!BM10 -> 4 | I6: ='Теорія ймовірності та математич'!AI10 -> 3 | J6: ='Соціологія'!AE10 -> 5 | K6: ='Технічне обслуговування ЕОМ'!BM10 -> 5 | L6: ='Технічне обслуговування ЕОМ'!BO10 -> 5 | M6: 3 | N6: =sum(D6:L6)/10 -> 3.5 | P6: =N6*0.9+O6*0.1 -> 3.15
A7: 8 | B7: Кисляков Дмитро Олександрович | D7: ='Економіка і планування виробниц'!AW11 -> 4 | E7: ='Захист інформації та безпека ПК'!U11 -> 4 | F7: ='Компютерні мережі'!CC11 -> 5 | G7: ='Організація баз даних'!BM11 -> 5 | H7: ='Основи програмної інженерії'!BM11 -> 5 | I7: ='Теорія ймовірності та математич'!AI11 -> 4 | J7: ='Соціологія'!AE11 -> 4 | K7: ='Технічне обслуговування ЕОМ'!BM11 -> 5 | L7: ='Технічне обслуговування ЕОМ'!BO11 -> 5 | M7: 5 | N7: =sum(D7:L7)/10 -> 4.1 | P7: =N7*0.9+O7*0.1 -> 3.69
A8: 10 | B8: Кутєхов Назарій Олександрович | D8: ='Економіка і планування виробниц'!AW13 -> н/д | E8: ='Захист інформації та безпека ПК'!U13 -> н/а | F8: ='Компютерні мережі'!CC13 -> н/а | G8: ='Організація баз даних'!BM13 -> н/а | H8: ='Основи програмної інженерії'!BM13 -> 3 | I8: ='Теорія ймовірності та математич'!AI13 -> 3 | J8: ='Соціологія'!AE13 -> 4 | K8: ='Технічне обслуговування ЕОМ'!BM13 -> 4 | L8: ='Технічне обслуговування ЕОМ'!BO13 -> 4 | N8: =sum(D8:L8)/10 -> 1.8 | P8: =N8*0.9+O8*0.1 -> 1.62 | Q8: академічна відпустка наказ №42-с/к від 01.05.26
A9: 11 | B9: Малюк Нікіта Сергійович | D9: ='Економіка і планування виробниц'!AW14 -> 3 | E9: ='Захист інформації та безпека ПК'!U14 -> 3 | F9: ='Компютерні мережі'!CC14 -> 3 | G9: ='Організація баз даних'!BM14 -> 3 | H9: ='Основи програмної інженерії'!BM14 -> 3 | I9: ='Теорія ймовірності та математич'!AI14 -> 3 | J9: 3 | K9: ='Технічне обслуговування ЕОМ'!BM14 -> 3 | L9: ='Технічне обслуговування ЕОМ'!BO14 -> 3 | M9: 4 | N9: =sum(D9:L9)/10 -> 2.7 | P9: =N9*0.9+O9*0.1 -> 2.43
A10: 17 | B10: Портаненко Гліб Олександрович | D10: ='Економіка і планування виробниц'!AW20 -> 3 | E10: ='Захист інформації та безпека ПК'!U20 -> 3 | F10: ='Компютерні мережі'!CC20 -> 3 | G10: ='Організація баз даних'!BM20 -> 3 | H10: ='Основи програмної інженерії'!BM20 -> 3 | I10: ='Теорія ймовірності та математич'!AI20 -> 3 | J10: ='Соціологія'!AE20 -> 4 | K10: ='Технічне обслуговування ЕОМ'!BM20 -> 3 | L10: ='Технічне обслуговування ЕОМ'!BO20 -> 3 | M10: 3 | N10: =sum(D10:L10)/10 -> 2.8 | P10: =N10*0.9+O10*0.1 -> 2.52
A11: 18 | B11: Ткаченко Кирило Сергійович | D11: 3 | E11: 3 | F11: ='Компютерні мережі'!CC21 -> 3 | G11: ='Організація баз даних'!BM21 -> 3 | H11: ='Основи програмної інженерії'!BM21 -> 3 | I11: ='Теорія ймовірності та математич'!AI21 -> 3 | J11: 3 | K11: ='Технічне обслуговування ЕОМ'!BM21 -> 3 | L11: ='Технічне обслуговування ЕОМ'!BO21 -> 4 | M11: 3 | N11: =sum(D11:L11)/10 -> 2.8 | P11: =N11*0.9+O11*0.1 -> 2.52 | Q11: 4
A12: 19 | B12: Царюк Єгор Андрійович | D12: ='Економіка і планування виробниц'!AW22 -> 4 | E12: ='Захист інформації та безпека ПК'!U22 -> 4 | F12: ='Компютерні мережі'!CC22 -> 5 | G12: ='Організація баз даних'!BM22 -> 5 | H12: ='Основи програмної інженерії'!BM22 -> 5 | I12: ='Теорія ймовірності та математич'!AI22 -> 4 | J12: ='Соціологія'!AE22 -> 5 | K12: ='Технічне обслуговування ЕОМ'!BM22 -> 5 | L12: ='Технічне обслуговування ЕОМ'!BO22 -> 5 | M12: 5 | N12: =sum(D12:L12)/10 -> 4.2 | P12: =N12*0.9+O12*0.1 -> 3.78
A13: 20 | B13: Дорубайло Ілля Олексійович | D13: ='Економіка і планування виробниц'!AW23 -> 3 | E13: ='Захист інформації та безпека ПК'!U23 -> н/а | F13: ='Компютерні мережі'!CC23 -> н/а | G13: ='Організація баз даних'!BM23 -> 3 | H13: ='Основи програмної інженерії'!BM23 -> 3 | I13: ='Теорія ймовірності та математич'!AI23 -> н/а | J13: 3 | K13: н/а | L13: н/д | N13: =sum(D13:L13)/10 -> 1.2 | P13: =N13*0.9+O13*0.1 -> 1.08 | Q13: академічна відпустка наказ №42-с/к від 01.05.26
D14: бігунок

Sheet Дискретна математика
B1: Назва дисципліни | C1: Дискретна математика
B2: Викладач | C2: Казмірчук О.І.
A3: № | B3: ПІБ студента | C3: 45944 | D3: 45947 | E3: 45951 | F3: 45954 | G3: 45958 | H3: 45961 | I3: 45962 | J3: 45965 | K3: 45968 | L3: 45972 | M3: 45975 | N3: 45979 | O3: 45982 | P3: 45986 | Q3: 45989 | R3: 45993 | S3: Тематична | T3: Скоригована | U3: 45996 | V3: 46000 | W3: 46003 | X3: 46004 | Y3: 46007 | Z3: 46010 | AA3: Тематична | AB3: Скоригована | AC3: Семестр | AE3: Залік
A4: 1. | B4: Гриценко Денис Сергійович | C4: н | D4: н/1 | E4: н | F4: н/1 | G4: н | H4: н | I4: н | J4: н | K4: н | L4: н | M4: н | N4: н | O4: н | P4: н | Q4: н | R4: н | S4: н/а | U4: н | V4: н | W4: н | X4: н | Y4: н | Z4: н | AA4: н/а | AC4: н/а | AE4: н/а | AF4: відрахований наказ №17-с/к від 27.02.2026
A5: 2. | B5: Гришков Едуард Сергійович | C5: н | D5: н/1 | E5: н | F5: н/1 | G5: н | H5: н | I5: н | J5: н | K5: н | L5: н | M5: н | N5: н | O5: н | P5: н | Q5: н | R5: н | S5: н/а | U5: н | V5: н | W5: н | X5: н | Y5: н | Z5: н | AA5: н/а | AC5: н/а | AE5: н/а | AF5: відрахований наказ №29-с/к від 27.03.26
A6: 3. | B6: Дворник Іван Миколайович | C6: н | D6: 1 | E6: н | F6: 1 | G6: н | H6: н | I6: н | K6: 3 | M6: 3 | O6: 3 | Q6: 3 | R6: 3 | S6: 3 | U6: н | V6: 3 | W6: н | X6: 3 | Z6: 3 | AA6: 3 | AC6: 3 | AE6: 3
A7: 4. | B7: Демченко Максим Сергійович | C7: н | D7: н/1 | E7: н | F7: н/1 | G7: н | H7: н | I7: н | J7: н | K7: н | L7: н | M7: н | N7: н | O7: н | P7: н | Q7: н | R7: н | S7: н/а | U7: н | V7: н | W7: н | X7: н | Y7: н | Z7: н | AA7: н/а | AC7: н/а | AE7: н/а | AF7: відрахований наказ №15-с/к від 18.02.2026
A8: 5. | B8: Івахненко Олександр Олександрович | C8: н | D8: н/1 | E8: н | F8: н/1 | G8: н | H8: н | I8: н | J8: н | K8: н | L8: н | M8: н | N8: н | O8: н | P8: н | Q8: н | R8: н | S8: н/а | U8: н | V8: н | W8: н | X8: н | Y8: н | Z8: н | AA8: н/а | AC8: н/а | AE8: н/а | AF8: академічна відпустка наказ №14-с/к від 16.02.26
A9: 6. | B9: Ішков Леонід Вікторович | D9: 4 | E9: 4 | F9: 4 | G9: 4 | H9: 4 | K9: 4 | L9: 4 | M9: 3 | O9: 4 | P9: 4 | Q9: 4 | R9: 4 | S9: 4 | U9: 4 | W9: 4 | Y9: 4 | Z9: 4 | AA9: 4 | AC9: 4 | AE9: 4
A10: 7. | B10: Каратаєв Данііл Сергійович | D10: 3 | F10: н/1 | G10: н | I10: н | J10: н | K10: 3 | L10: н | M10: 3 | N10: н | O10: 3 | P10: н | Q10: 3 | R10: 3 | S10: 3 | U10: н | V10: 3 | W10: 3 | Y10: 3 | Z10: 3 | AA10: 3 | AC10: 3 | AE10: 3
A11: 8. | B11: Кисляков Дмитро Олександрович | D11: 1 | E11: 4 | F11: 4 | G11: 4 | H11: 4 | K11: 4 | L11: 4 | M11: 4 | N11: 4 | O11: н | P11: н/3 | Q11: н/4 | R11: н/4 | S11: 4 | U11: 4 | V11: н | W11: н | X11: н/4 | Y11: 4 | Z11: 4 | AA11: 4 | AC11: 4 | AE11: 4
A12: 9. | B12: Ковальчук Арсеній Борисович | C12: н | D12: н/1 | E12: н | F12: н/1 | G12: н | H12: н | I12: н | J12: н | K12: н | L12: н | M12: н | N12: н | O12: н | P12: н | Q12: н | R12: н | S12: н/а | U12: н | V12: н | W12: н | X12: н | Y12: н | Z12: н | AA12: н/а | AC12: н/а | AE12: н/а | AF12: відрахований наказ №17-с/к від 27.02.2026
A13: 10. | B13: Кутєхов Назарій Олександрович | C13: н | D13: н/1 | E13: н | F13: н/3 | G13: н | H13: н | I13: н/3 | J13: н | K13: н | L13: н | M13: н | N13: н | O13: н/3 | P13: н | Q13: н/3 | R13: н | S13: н/а | U13: н | V13: н | W13: н | X13: н | Y13: н | Z13: н | AA13: н/а | AC13: н/а | AE13: н/а | AF13: 3
A14: 11. | B14: Малюк Нікіта Сергійович | C14: н | D14: н/1 | E14: н | F14: 1 | G14: н | H14: н | I14: н | K14: 2 | N14: н | O14: н | P14: н | Q14: н | R14: н | S14: 3 | V14: н | W14: н | X14: н | Y14: н | Z14: н | AA14: 3 | AC14: 3 | AE14: 3
A15: 12. | B15: Мезенцев Кирило Анатолійович | C15: н | D15: н/1 | E15: н | F15: н/1 | G15: н | H15: н | I15: н | J15: н | K15: н | L15: н | M15: н | N15: н | O15: н | P15: н | Q15: н | R15: н | S15: н/а | U15: н | V15: н | W15: н | X15: н | Y15: н | Z15: н | AA15: н/а | AC15: н/а | AE15: н/а | AF15: відрахований наказ №18-с/к від 04.04.26
A16: 13. | B16: Надіров Расім Аріфович | C16: н | D16: н/1 | E16: н | F16: н/1 | G16: н | H16: н | I16: н | J16: н | K16: н | L16: н | M16: н | N16: н | O16: н | P16: н | Q16: н | R16: н | S16: н/а | U16: н | V16: н | W16: н | X16: н | Y16: н | Z16: н | AA16: н/а | AC16: н/а | AE16: н/а | AF16: академічна відпустка наказ №16-с/к від 25.02.26
A17: 14. | B17: Онищенко Ярослав Віталійович | C17: н | D17: н/1 | E17: н | F17: н/1 | G17: н | H17: н | I17: н | J17: н | K17: н | L17: н | M17: н | N17: н | O17: н | P17: н | Q17: н | R17: н | S17: н/а | U17: н | V17: н | W17: н | X17: н | Y17: н | Z17: н | AA17: н/а | AC17: н/а | AE17: н/а | AF17: відрахований наказ №17-с/к від 27.02.2026
A18: 15. | B18: Павлюк Дмитро Ігорович | C18: н | D18: н/1 | E18: н | F18: н/1 | G18: н | H18: н | I18: н | J18: н | K18: н | L18: н | M18: н | N18: н | O18: н | P18: н | Q18: н | R18: н | S18: н/а | U18: н | V18: н | W18: н | X18: н | Y18: н | Z18: н | AA18: н/а | AC18: н/а | AE18: н/а | AF18: відрахований наказ №26-с/к від 17.03.2026
A19: 16. | B19: Плетій Андрій Анатолійович | C19: н | D19: н/1 | E19: н | F19: н | G19: н | H19: н | I19: н | J19: н | K19: н | L19: н | M19: н | N19: н | O19: н | P19: н | Q19: н | R19: н | S19: н/а | U19: н | V19: н | W19: н | X19: н | Y19: н | Z19: н | AA19: н/а | AC19: н/а | AE19: н/а | AF19: відрахований наказ №18-с/к від 04.04.26
A20: 17. | B20: Портаненко Гліб Олександрович | C20: н | D20: н/1 | E20: н | F20: н | G20: н | H20: н | I20: н | K20: н | L20: н | M20: н | N20: н | O20: н | P20: н | Q20: н | R20: н | S20: 3 | U20: н | V20: н | W20: н | X20: н | Y20: н | Z20: н | AA20: 3 | AC20: 3 | AE20: 3
A21: 18. | B21: Ткаченко Кирило Сергійович | D21: н/1 | F21: 3 | G21: 1 | I21: н | K21: н | L21: н\3 | M21: н | P21: н\3 | Q21: н\3 | R21: н | S21: н/а | T21: 3 | U21: н | V21: н/2 | W21: н | X21: н | Y21: н | Z21: н | AA21: 2 | AB21: 3 | AC21: 2 | AE21: 2 | AF21: 3
A22: 19. | B22: Царюк Єгор Андрійович | D22: н/3 | F22: н/4 | G22: н/3 | H22: н/3 | I22: н | K22: н/3 | L22: 4 | M22: 3 | N22: н/3 | O22: н | P22: н\3 | Q22: н\3 | R22: н/3 | S22: 3 | U22: н\3 | V22: 3 | W22: н | X22: н/3 | Y22: н\3 | Z22: н/3 | AA22: 3 | AC22: 3 | AE22: 3
A23: № | B23: Дата | C23: Години | D23: Тема заняття | T23: Домашня робота
A24: 1 | B24: 45944 | C24: 2 | D24: Зміст та задачі дискретної математики. Поняття множини. Способи задання множини. | T24: Бондаренко, п.1.1 ст. 9-13, №1-№4 ст.13
A25: 2 | B25: 45947 | C25: 2 | D25: Відношення між множинам. Геометричне зображення множин. | T25: п.1.3 ст. 18-20, №1-№3 ст. 20
A26: 3 | B26: 45951 | C26: 2 | D26: Основні операції над множинами.Практична робота . | T26: п.1.4 ст. 20-29, № 1, №4, №6, №8 ст. 22, №4 ст. 26
A27: 4 | B27: 45954 | C27: 2 | D27: Основні закони теорії множин. | T27: п.1.2 ст. 14-16, №", №4, №5, №6 ст. 17
A28: 5 | B28: 45958 | C28: 2 | D28: Декартовий добуток множин. Самостійна робота. | T28: повт. п. 1.1-п.1.4, №1-№4 (в зошиті)
A29: 6 | B29: 45961 | C29: 2 | D29: Поняття відношення. Способи задання відношень. | T29: п.2.1 ст.30-35, №1, №2, №5, №7 ст. 36
A30: 7 | B30: 01.11.2025 відпрацьовування за 23 грудня | C30: 2 | D30: Образи і прообрази елементів і множин відносно відношень. | T30: п. 2.2 ст. 37-41, №1, №2, №4 ст. 42
A31: 8 | B31: 45965 | C31: 2 | D31: Властивості бінарних відношень. | T31: п.2.3 ст. 42-45, № 1, №2 ст. 46
A32: 9 | B32: 45968 | C32: 2 | D32: Спеціальні бінарні відношення. Обернені бінарні операції. Практична робота. | T32: п.2.4 ст. 47-51, №2, №3, №4 ст. 52
A33: 10 | B33: 45972 | C33: 2 | D33: Поняття функції та відображення. Класифікація функцій. Потужність множин і зліченність | T33: п.2.5-2.6 ст. 54, №1-№4 ст. 60
A34: 11 | B34: 45975 | C34: 2 | D34: Поняття бінарної алгебраїчної операції та їх властивості . Практична робота | T34: п.3.1-3.5 ст. 73-85 , №1, №3, №4 ст. 85
A35: 12 | B35: 45979 | C35: 2 | D35: Правило добутку. Формула включень та виключення. Комбінаторні схеми. | T35: п.10.1 - 10.5 ст. 408-431, № 1,2,3 ст. 424, ст. 429
A36: 13 | B36: 45982 | C36: 2 | D36: Комбінаторні задачі з обмеженнями. Комбінаторика розбиття. Практична робота. | T36: п.10.6 ст. 432-433, №1,2.3 в зошиті
A37: 14 | B37: 45986 | C37: 2 | D37: Рекурентні співвідношення. Числа Фібоначчі. Розв'язування рекурентних співвідношень. Лінійні рекурентні співвідношення з сталими коефіцієнтами. | T37: п.10.6 ст. 433-450, № 1, №2, №3 ст. 459-450
A38: 15 | B38: 45989 | C38: 2 | D38: Комбінаторика і ряди. Породжуючі функції. Біном Ньютона. Поліномна формула. | T38: п.10.5 ст. 431-432, №1,2,3 в зошиті
A39: 16 | B39: 45993 | C39: 2 | D39: Контрольна робота №1 | T39: повторити матеріал і основні формули.
A40: 17 | B40: 45996 | C40: 2 | D40: Основні поняття. Зображення графа. | T40: п.6.1-6.4 ст. 239-248, № 2.4,6,8 ст. 246
...

Sheet Архітектура компютерів
B1: Назва дисципліни | C1: Архітектура комп'ютерів (КМ-42)
B2: Викладач | C2: Науменко П.В.
A3: № | B3: ПІБ студента | C3: 45944 | D3: 45946 | E3: 45951 | F3: 45953 | G3: 45958 | H3: 45960 | I3: 45962 | J3: 45965 | K3: Тематична | M3: 45967 | N3: 45972 | O3: 45974 | P3: 45979 | Q3: 45981 | R3: 45986 | S3: 45988 | T3: 45990 | U3: Тематична | W3: 45993 | X3: 45995 | Y3: 46000 | Z3: 46002 | AA3: 46007 | AB3: Тематична | AD3: Семестрова | AF3: Екзамен
A4: 1. | B4: Гриценко Денис Сергійович | C4: н | D4: н | E4: н | F4: 5 | G4: н | H4: 2 | I4: н | J4: н | K4: 3 | M4: н | N4: н | O4: н | P4: н | Q4: н | R4: н | S4: н | T4: н | U4: н/а | W4: н | X4: н | Y4: н | Z4: н | AA4: н | AB4: н/а | AD4: н/а | AF4: н/д | AG4: відрахований наказ №17-с/к від 27.02.2026
A5: 2. | B5: Гришков Едуард Сергійович | C5: н | D5: н | E5: н | F5: н | G5: н | H5: н | I5: н | J5: н | K5: н/а | M5: н | N5: н | O5: н | P5: н | Q5: н | R5: н | S5: н | T5: н | U5: н/а | W5: н | X5: н | Y5: н | Z5: н | AA5: н | AB5: н/а | AD5: н/а | AF5: н/д | AG5: відрахований наказ №29-с/к від 27.03.26
A6: 3. | B6: Дворник Іван Миколайович | D6: н | E6: н | F6: 5 | G6: н | H6: 5 | I6: н | J6: 5 | K6: 5 | N6: 2 | P6: н | Q6: н | T6: н | U6: н/а | V6: 3 | Z6: н | AB6: н/а | AC6: 3 | AD6: 4 | AF6: 4
A7: 4. | B7: Демченко Максим Сергійович | C7: н | D7: н | E7: н | F7: н | G7: н | H7: н | I7: н | J7: н | K7: н/а | M7: н | N7: н | O7: н | P7: н | Q7: н | R7: н | S7: н | T7: н | U7: н/а | W7: н | X7: н | Y7: н | Z7: н | AA7: н | AB7: н/а | AD7: н/а | AF7: н/д | AG7: відрахований наказ №15-с/к від 18.02.2026
A8: 5. | B8: Івахненко Олександр Олександрович | C8: н | D8: н | E8: н | F8: н | G8: н | H8: н | I8: н | J8: н | K8: н/а | M8: н | N8: н | O8: н | P8: н | Q8: н | R8: н | S8: н | T8: н | U8: н/а | W8: н | X8: н | Y8: н | Z8: н | AB8: н/а | AD8: н/а | AF8: н/д | AG8: академічна відпустка наказ №14-с/к від 16.02.26
A9: 6. | B9: Ішков Леонід Вікторович | E9: 5 | F9: 5 | G9: 2 | H9: 5 | J9: 5 | K9: 4 | N9: 5 | Q9: 4 | T9: 5 | U9: 5 | X9: 4 | Y9: 5 | AA9: 5 | AB9: 5 | AD9: 5 | AF9: 5
A10: 7. | B10: Каратаєв Данііл Сергійович | D10: н | E10: 2 | F10: 4 | G10: н | H10: н | I10: н | J10: 3 | K10: 3 | M10: н | N10: 2 | Q10: 4 | T10: 5 | U10: 4 | Y10: н | AB10: н/а | AC10: 4 | AD10: 4 | AF10: 4
A11: 8. | B11: Кисляков Дмитро Олександрович | E11: 5 | F11: 5 | G11: 3 | H11: 5 | I11: н | J11: 5 | K11: 5 | N11: 5 | Q11: 4 | R11: н | T11: 5 | U11: 5 | X11: 4 | Y11: 5 | Z11: 4 | AB11: 4 | AD11: 5 | AF11: 5
A12: 9. | B12: Ковальчук Арсеній Борисович | C12: н | D12: н | E12: н | F12: н | G12: н | H12: н | I12: н | J12: н | K12: н/а | M12: н | N12: н | O12: н | P12: н | Q12: н | R12: н | S12: н | T12: н | U12: н/а | W12: н | X12: н | Y12: н | Z12: н | AA12: н | AB12: н/а | AD12: н/а | AF12: н/д | AG12: відрахований наказ №17-с/к від 27.02.2026
A13: 10. | B13: Кутєхов Назарій Олександрович | C13: н | D13: н | E13: н | F13: н | G13: н | H13: н | I13: н | J13: н | K13: н/а | L13: 3 | M13: н | N13: н | O13: н | P13: н | Q13: н | R13: н | S13: н | T13: н | U13: н/а | V13: 3 | W13: н | X13: н | Y13: н | Z13: н | AA13: н | AB13: н/а | AD13: н/а | AF13: н/д | AG13: 3
A14: 11. | B14: Малюк Нікіта Сергійович | C14: н | D14: н | E14: н | F14: 5 | G14: н | H14: 5 | I14: н | J14: 5 | K14: 5 | N14: н | O14: н | P14: н | Q14: н | T14: н | U14: н/а | V14: 3 | Y14: 5 | Z14: н | AB14: н/а | AC14: 4 | AD14: 4 | AF14: 4
A15: 12. | B15: Мезенцев Кирило Анатолійович | C15: н | D15: н | E15: н | F15: н | G15: н | H15: н | I15: н | J15: н | K15: н/а | M15: н | N15: н | O15: н | P15: н | Q15: н | R15: н | S15: н | T15: н | U15: н/а | W15: н | X15: н | Y15: н | Z15: н | AA15: н | AB15: н/а | AD15: н/а | AF15: н/д | AG15: відрахований наказ №18-с/к від 04.04.26
A16: 13. | B16: Надіров Расім Аріфович | C16: н | D16: н | E16: н | F16: н | G16: н | H16: н | I16: н | J16: н | K16: н/а | M16: н | N16: н | O16: н | P16: н | Q16: н | R16: н | S16: н | T16: н | U16: н/а | W16: н | X16: н | Y16: н | Z16: н | AA16: н | AB16: н/а | AD16: н/а | AF16: н/д | AG16: академічна відпустка наказ №16-с/к від 25.02.26
A17: 14. | B17: Онищенко Ярослав Віталійович | C17: н | D17: н | E17: н | F17: н | G17: н | H17: н | I17: н | J17: н | K17: н/а | M17: н | N17: н | O17: н | P17: н | Q17: н | R17: н | S17: н | T17: н | U17: н/а | W17: н | X17: н | Y17: н | Z17: н | AA17: н | AB17: н/а | AD17: н/а | AF17: н/д | AG17: відрахований наказ №17-с/к від 27.02.2026
A18: 15. | B18: Павлюк Дмитро Ігорович | C18: н | D18: н | E18: н | F18: н | G18: н | H18: н | I18: н | J18: н | K18: н/а | M18: н | N18: н | O18: н | P18: н | Q18: н | R18: н | S18: н | T18: н | U18: н/а | W18: н | X18: н | Y18: н | Z18: н | AA18: н | AB18: н/а | AD18: н/а | AF18: н/д | AG18: відрахований наказ №26-с/к від 17.03.2026
A19: 16. | B19: Плетій Андрій Анатолійович | C19: н | D19: н | E19: н | F19: н | G19: н | H19: н | I19: н | J19: н | K19: н/а | M19: н | N19: н | O19: н | P19: н | Q19: н | R19: н | S19: н | T19: н | U19: н/а | W19: н | X19: н | Y19: н | Z19: н | AA19: н | AB19: н/а | AD19: н/а | AF19: н/д | AG19: відрахований наказ №18-с/к від 04.04.26
A20: 17. | B20: Портаненко Гліб Олександрович | C20: н | D20: н | E20: н | F20: н | G20: н | H20: н | I20: н | K20: н/а | L20: 3 | M20: н | N20: н | O20: н | P20: н | Q20: н | R20: н | S20: н | T20: н | U20: н/а | V20: 3 | Z20: н | AB20: н/а | AC20: 3 | AD20: 3 | AF20: 3
A21: 18. | B21: Ткаченко Кирило Сергійович | E21: 3 | G21: 2 | H21: 3 | I21: н | J21: 2 | K21: 3 | N21: н | P21: н | Q21: н | S21: н | U21: н/а | V21: 3 | Z21: н | AB21: н/а | AC21: 3 | AD21: 3 | AF21: 3
A22: 19. | B22: Царюк Єгор Андрійович | E22: н | F22: н | G22: н | H22: н | I22: н | J22: н | K22: н/а | L22: 3 | N22: н | O22: н | P22: н | Q22: н | R22: н | S22: н | T22: н | U22: н/а | V22: 3 | W22: н | Y22: 5 | Z22: 2 | AA22: н | AB22: 3 | AD22: 3 | AF22: 3
A23: 20. | B23: Дорубайло Ілля Олексійович
A24: № | B24: Дата | C24: Години | D24: Тема заняття | M24: Домашня робота
A25: 1 | B25: 45944 | C25: 2 | D25: Практ. роб. з Мікропроцесор. Двошинна та тришинна структури МПС (мікропроцесорних систем).
A26: 2 | B26: 45946 | C26: 2 | D26: Багаторівнева пам'ять комп’ютерів. Надоперативна, оперативна, буферна (кеш) пам’ять.
A27: 3 | B27: 45951 | C27: 2 | D27: Практ. роб. з Багаторівнева пам'ять комп’ютерів.
A28: 4 | B28: 45953 | C28: 2 | D28: Практ. роб. з Надоперативна, оперативна, буферна (кеш) пам’ять.
B29: жовтень | C29: 8
A30: 5 | B30: 45958 | C30: 2 | D30: Загальні принципи організації пам'яті ЕОМ. Організація сторінкової та сегментносторінкової віртуальної пам’яті.
A31: 6 | B31: 45960 | C31: 2 | D31: Практ. роб. з Загальні принципи організації пам'яті ЕОМ.
A32: 7 | B32: 45962 | C32: 2 | D32: Практ. роб. з Організація сторінкової та сегментносторінкової віртуальної пам’яті.
A33: 8 | B33: 45965 | C33: 2 | D33: Взаємодія усіх рівнів пам’яті. Багатопрограмний режим роботи процесорів. Захист розділів пам’яті.
A34: 9 | B34: 45967 | C34: 2 | D34: Практ. роб. з Взаємодія усіх рівнів пам’яті.
A35: 10 | B35: 45972 | C35: 2 | D35: Практ. роб. з Багатопрограмний режим роботи процесорів.
A36: 11 | B36: 45974 | C36: 2 | D36: Практ. роб. з Захист розділів пам’яті.
B37: листопад | C37: 14
A38: 12 | B38: 45979 | C38: 2 | D38: Режими роботи процесора з зовнішніми пристроями. Архітектура засобів вводу-виводу інформації.
A39: 13 | B39: 45981 | C39: 2 | D39: Практ. роб. з Режими роботи процесора з зовнішніми пристроями.
A40: 14 | B40: 45986 | C40: 2 | D40: Програмний обмін даними, обробка переривань, організація прямого доступу до пам'яті.
...

Sheet Економіка і планування виробниц
B1: Назва дисципліни | C1: Економіка і планування виробництва
B2: Викладач | C2: Устюгова Ж.В.
A3: № | B3: ПІБ студента | C3: 46048 | D3: 46049 | E3: 46051 | F3: 46055 | G3: 46056 | H3: 46058 | I3: 46062 | J3: 46063 | K3: тематична | M3: 46065 | N3: 46069 | O3: 46070 | P3: 46072 | Q3: 46076 | R3: 46077 | S3: 46079 | T3: 46083 | U3: тематична | W3: 46084 | X3: 46086 | Y3: 46090 | Z3: 46091 | AA3: 46093 | AB3: 46097 | AC3: 46100 | AD3: 46104 | AE3: тематична | AG3: 46107 | AH3: 46108 | AI3: 46111 | AJ3: 46112 | AK3: 46114 | AL3: 46115 | AM3: 46118 | AN3: 46121 | AO3: 46122 | AP3: 46125 | AQ3: 46126 | AR3: 46128 | AS3: тематична | AU3: семестр | AW3: іспит
A4: 1. | B4: Гриценко Денис Сергійович | C4: н | D4: н | E4: н | F4: н | G4: н | H4: н | I4: н | J4: н | K4: н/а | M4: н | N4: н | O4: н | P4: н | Q4: н | R4: н | S4: відрахований наказ №17-с/к від 27.02.2026 | AE4: - | AG4: відрахований наказ №17-с/к від 27.02.2026 | AS4: - | AU4: - | AW4: - | AX4: відрахований наказ №17-с/к від 27.02.2026
A5: 2. | B5: Гришков Едуард Сергійович | C5: н | D5: н | E5: н | F5: н | G5: н | H5: н | I5: н | J5: н | K5: н/а | M5: н | N5: н | O5: н | P5: н | Q5: н | R5: н | S5: н | T5: н | U5: н/а | W5: н | X5: н | Y5: н | Z5: н | AA5: н | AB5: н | AC5: н | AD5: н | AE5: н/а | AG5: н | AH5: н | AI5: н | AJ5: н | AK5: н | AL5: н | AN5: 2 | AS5: - | AU5: - | AW5: - | AX5: відрахований наказ №29-с/к від 27.03.26
A6: 3. | B6: Дворник Іван Миколайович | C6: 2 | D6: 2 | E6: 2 | F6: 2 | G6: 2 | H6: 2 | I6: 2 | J6: 2 | K6: 2 | L6: 3 | M6: 2 | N6: 2 | O6: 2 | P6: 2 | Q6: 2 | R6: 2 | S6: 2 | T6: 2 | U6: 2 | V6: 3 | W6: 2 | X6: 2 | Y6: 2 | Z6: 2 | AA6: 2 | AB6: н | AC6: 2 | AD6: 2 | AE6: 2 | AF6: 3 | AG6: 2 | AH6: 2 | AI6: 3 | AJ6: 3 | AK6: 3 | AL6: 3 | AM6: 3 | AN6: 3 | AO6: 3 | AP6: 2 | AQ6: 3 | AR6: 3 | AS6: 3 | AU6: 3 | AW6: 3
A7: 4. | B7: Демченко Максим Сергійович | C7: н | D7: н | E7: н | F7: н | G7: н | H7: н | I7: н | J7: н | K7: н/а | M7: н | N7: н | O7: н | P7: відрахований наказ №15-с/к від 18.02.2026 | W7: відрахований наказ №15-с/к від 18.02.2026 | AE7: - | AG7: відрахований наказ №15-с/к від 18.02.2026 | AS7: - | AU7: - | AW7: - | AX7: відрахований наказ №15-с/к від 18.02.2026
A8: 5. | B8: Івахненко Олександр Олександрович | C8: н | D8: н | E8: н | F8: н | G8: н | H8: н | I8: н | J8: н | K8: н/а | M8: н | N8: н | O8: н | P8: академічна відпустка наказ №14-с/к від 16.02.26 | W8: академічна відпустка наказ №14-с/к від 16.02.26 | AE8: - | AG8: академічна відпустка наказ №14-с/к від 16.02.26 | AS8: - | AU8: - | AW8: - | AX8: академічна відпустка наказ №14-с/к від 16.02.26
A9: 6. | B9: Ішков Леонід Вікторович | D9: 5 | E9: 5 | F9: 5 | G9: 5 | H9: 5 | I9: 5 | K9: 5 | M9: 5 | N9: 5 | P9: 5 | S9: 5 | T9: 5 | U9: 5 | X9: 5 | Z9: 5 | AC9: 5 | AE9: 5 | AH9: 5 | AI9: 5 | AL9: 5 | AN9: 4 | AP9: 5 | AS9: 5 | AU9: 5 | AW9: 5
A10: 7. | B10: Каратаєв Данііл Сергійович | D10: 4 | E10: 3 | F10: 4 | G10: 3 | H10: 5 | I10: 3 | K10: 4 | M10: 4 | N10: 4 | O10: 5 | P10: 5 | S10: 2 | T10: 2 | U10: 4 | X10: 5 | Z10: 5 | AC10: 5 | AE10: 5 | AH10: 4 | AI10: 5 | AL10: 5 | AN10: 4 | AP10: 4 | AQ10: н | AS10: 4 | AU10: 4 | AW10: 4
A11: 8. | B11: Кисляков Дмитро Олександрович | D11: 5 | E11: 5 | F11: 5 | G11: 5 | H11: 4 | K11: 5 | M11: 4 | N11: 4 | O11: 2 | P11: 5 | S11: 5 | T11: 5 | U11: 4 | X11: 5 | Z11: 5 | AD11: 4 | AE11: 5 | AH11: 4 | AI11: 5 | AL11: 5 | AN11: 4 | AP11: 4 | AS11: 4 | AU11: 4 | AW11: 4
A12: 9. | B12: Ковальчук Арсеній Борисович | C12: н | D12: н | E12: н | F12: н | G12: н | H12: н | I12: н | J12: н | K12: н/а | M12: н | N12: н | O12: н | P12: н | Q12: н | S12: відрахований наказ №17-с/к від 27.02.2026 | AE12: - | AG12: відрахований наказ №17-с/к від 27.02.2026 | AS12: - | AU12: - | AW12: - | AX12: відрахований наказ №17-с/к від 27.02.2026
A13: 10. | B13: Кутєхов Назарій Олександрович | C13: н | D13: н | E13: н | F13: н | G13: н | H13: н | I13: н | J13: н | K13: н/а | M13: 2 | N13: 2 | O13: 2 | P13: 2 | Q13: 2 | R13: 2 | S13: 2 | T13: 2 | U13: 2 | W13: 2 | X13: 2 | Y13: 2 | Z13: 2 | AA13: 2 | AB13: н | AC13: 2 | AD13: 2 | AE13: 2 | AG13: 2 | AH13: 2 | AI13: 2 | AJ13: 2 | AK13: 2 | AL13: 2 | AM13: 2 | AN13: 2 | AO13: 2 | AP13: 2 | AQ13: н | AR13: н | AS13: 2 | AU13: 2 | AW13: н/д
A14: 11. | B14: Малюк Нікіта Сергійович | D14: 2 | E14: 2 | F14: 2 | G14: 2 | H14: 2 | I14: 2 | J14: 2 | K14: 2 | L14: 3 | M14: 2 | N14: 2 | O14: 2 | P14: 2 | Q14: 2 | R14: 2 | S14: 2 | T14: 2 | U14: 2 | V14: 3 | W14: 2 | X14: 2 | Y14: 2 | Z14: 2 | AA14: 2 | AB14: 3 | AC14: 3 | AD14: 3 | AE14: 2 | AF14: 3 | AH14: 3 | AI14: 3 | AJ14: 3 | AK14: 3 | AL14: 3 | AN14: 2 | AO14: 3 | AP14: 3 | AQ14: 3 | AR14: 3 | AS14: 3 | AU14: 3 | AW14: 3
A15: 12. | B15: Мезенцев Кирило Анатолійович | C15: 2 | D15: 4 | E15: 2 | F15: 2 | G15: 2 | H15: 2 | I15: 2 | J15: 2 | K15: 2 | M15: н | N15: н | O15: н | P15: н | Q15: н | R15: відрахований наказ № | U15: - | W15: відрахований наказ №18-с/к від 04.04.26 | AE15: - | AG15: відрахований наказ №18-с/к від 04.04.26 | AS15: - | AU15: - | AW15: - | AX15: відрахований наказ №18-с/к від 04.04.26
A16: 13. | B16: Надіров Расім Аріфович | C16: н | D16: н | E16: н | F16: н | G16: н | H16: н | I16: н | J16: н | K16: н/а | M16: н | N16: н | O16: н | P16: н | Q16: н | R16: академічна відпустка наказ №16-с/к від 25.02.26 | AE16: - | AG16: академічна відпустка наказ №16-с/к від 25.02.26 | AS16: - | AU16: - | AW16: - | AX16: академічна відпустка наказ №16-с/к від 25.02.26
A17: 14. | B17: Онищенко Ярослав Віталійович | C17: н | D17: н | E17: н | F17: н | G17: н | H17: н | I17: н | J17: н | K17: н/а | M17: н | N17: н | O17: н | P17: н | Q17: н | R17: відрахований наказ №17-с/к від 27.02.2026 | AE17: - | AG17: відрахований наказ №17-с/к від 27.02.2026 | AS17: - | AU17: - | AW17: - | AX17: відрахований наказ №17-с/к від 27.02.2026
A18: 15. | B18: Павлюк Дмитро Ігорович | C18: н | D18: н | E18: н | F18: н | G18: н | H18: н | I18: н | J18: н | K18: н/а | M18: н | N18: н | O18: н | P18: н | Q18: н | R18: н | S18: н | T18: н | U18: н/а | W18: н | X18: н | Y18: н | Z18: н | AA18: н | AB18: н | AC18: н | AD18: н | AE18: н/а | AG18: відрахований наказ №26-с/к від 17.03.2026 | AS18: - | AU18: - | AW18: - | AX18: відрахований наказ №26-с/к від 17.03.2026
A19: 16. | B19: Плетій Андрій Анатолійович | C19: 2 | D19: 2 | E19: 2 | F19: 2 | G19: 2 | H19: 2 | I19: 2 | J19: 2 | K19: 2 | M19: н | N19: н | O19: н | P19: н | Q19: н | R19: відрахований наказ № | U19: - | W19: відрахований наказ №18-с/к від 04.04.26 | AE19: - | AG19: відрахований наказ №18-с/к від 04.04.26 | AS19: - | AU19: - | AW19: - | AX19: відрахований наказ №18-с/к від 04.04.26
A20: 17. | B20: Портаненко Гліб Олександрович | C20: 2 | D20: 2 | E20: 2 | F20: 2 | G20: 2 | H20: 2 | I20: 2 | J20: 2 | K20: 2 | L20: 3 | M20: 2 | N20: 2 | O20: 2 | P20: 2 | R20: 2 | S20: 2 | T20: 2 | U20: 2 | V20: 3 | W20: 2 | X20: 2 | Z20: 2 | AA20: 2 | AB20: н | AC20: 2 | AD20: 2 | AE20: 2 | AF20: 3 | AG20: 2 | AH20: 2 | AI20: 3 | AJ20: 3 | AK20: 2 | AL20: 3 | AM20: 2 | AN20: 3 | AO20: 3 | AP20: 2 | AQ20: 3 | AR20: 3 | AS20: 3 | AU20: 3 | AW20: 3
A21: 18. | B21: Ткаченко Кирило Сергійович | C21: н | D21: н | E21: н | F21: н | G21: н | H21: н | I21: н | J21: н | K21: н/а | L21: 3 | M21: н | N21: н | O21: н | P21: н | Q21: н | R21: н | S21: н | T21: н | U21: н/а | V21: 3 | W21: н | X21: н | Z21: н | AA21: н | AB21: н | AC21: н | AE21: н/а | AF21: 3 | AG21: н | AH21: н | AI21: н | AJ21: н | AK21: н | AL21: н | AM21: н | AN21: н | AO21: н | AP21: н | AQ21: н | AR21: н | AS21: н/а | AT21: 3 | AU21: н/а | AV21: 3 | AW21: н/д | AX21: 3
A22: 19. | B22: Царюк Єгор Андрійович | C22: 2 | D22: 5 | E22: 2 | F22: 2 | G22: 5 | H22: 2 | I22: 5 | J22: 2 | K22: 3 | N22: 4 | O22: 3 | P22: 3 | Q22: 4 | R22: 4 | S22: 5 | T22: 4 | U22: 4 | W22: 5 | X22: 5 | Y22: 5 | Z22: 5 | AA22: 5 | AB22: 4 | AC22: 4 | AD22: 5 | AE22: 5 | AG22: 5 | AH22: 4 | AI22: 5 | AJ22: 5 | AK22: 5 | AL22: 5 | AP22: 5 | AQ22: н | AS22: 5 | AU22: 4 | AW22: 4
A23: 20. | B23: Дорубайло Ілля Олексійович | C23: н | D23: н | E23: 3 | F23: 3 | G23: н | H23: 4 | I23: н | J23: 3 | K23: 3 | M23: 3 | N23: 3 | O23: 3 | P23: 3 | Q23: н | R23: н | S23: н | T23: н | U23: 3 | W23: н | X23: 3 | Z23: 3 | AA23: н | AB23: н | AC23: 3 | AE23: 3 | AG23: н | AH23: 3 | AI23: 3 | AJ23: н | AK23: н | AL23: 3 | AM23: н | AN23: н | AO23: 3 | AP23: н | AQ23: н | AS23: 3 | AU23: 3 | AW23: 3
A24: № | B24: Дата | C24: Години | D24: Тема заняття | N24: Домашня робота | AL24: есе
A25: 1 | B25: 46048 | C25: 2 | D25: Лекція 1. Основи економіки і виробництва в ринкових умовах | N25: Дослідити поняття "Безумовний базовий дохід"
A26: 2 | B26: 46049 | C26: 2 | D26: Семінарське заняття 1 | N26: індивідуальні роботи у Classroom
A27: 3 | B27: 46051 | C27: 2 | D27: Лекція 2. Підприємство як суб’єкт господарювання | N27: Бойчик, с.22-30
A28: 4 | B28: 46055 | C28: 2 | D28: Лекція 3. Організація управління та структура підприємства | N28: Бойчик, 47-54
A29: 5 | B29: 46056 | C29: 2 | D29: Семінарське заняття 2 | N29: Бойчик, 54-59
A30: 6 | B30: 46058 | C30: 2 | D30: Лекція 4. Основний капітал підприємства | N30: Бойчик, 165-174
A31: 7 | B31: 46062 | C31: 2 | D31: Лекція 5. Оборотний капітал підприємства | N31: Бойчик, 184-189
A32: 8 | B32: 46063 | C32: 2 | D32: Семінарсько-практичне заняття 3 | N32: Бойчик, 177-184
A33: 9 | B33: 46065 | C33: 2 | D33: Лекція 6. Персонал підприємства та продуктивність праці | N33: Бойчик, 133-138
A34: 10 | B34: 46069 | C34: 2 | D34: Семінарсько-практичне заняття 4 | N34: Бойчик, 137-140
A35: 11 | B35: 46070 | C35: 2 | D35: Семінарсько-практичне заняття 5 | N35: Бойчик, 143-145
A36: 12 | B36: 46072 | C36: 2 | D36: Лекція 7. Заробітна плата, її суть та значення на підприємстві | N36: Бойчик, 153-155
... A60: 36 | B60: 46128 | C60: 2 | D60: Семінарсько-практичне заняття 14 | N60: підготовка до іспиту
B61: 46128 | C61: 2 | D61: Проведення консультації перед іспитом
B62: 46136 | D62: Іспит
C64: Програму виконано в повному обсязі. За планом - 72 ауд. год, фактично - 72 ауд. год.

Sheet Захист інформації та безпека ПК
B1: Назва дисципліни | C1: Захист інформації та безпека ПК
B2: Викладач | C2: Коваль А.М.
A3: № | B3: ПІБ студента | C3: 46049 | D3: 46056 | E3: 46063 | F3: 46070 | G3: 46077 | H3: 46084 | I3: Тематична | K3: 46091 | L3: 46098 | M3: 46105 | N3: 46112 | O3: 46119 | P3: 46126 | Q3: Тематична | S3: Семестрова | U3: Залік
A4: 1. | B4: Гриценко Денис Сергійович | C4: 4 | D4: 4 | E4: 4 | F4: 4 | G4: н | H4: н | I4: =IF(OR(ROUND(SUM(C4:H4)/MAX(6,COUNTIF(C4:H4, ">0")), 0) <= 1, COUNTIF(C4:H4, ">0") = 0), "н/а", ROUND(SUM(C4:H4)/MAX(6,COUNTIF(C4:H4, ">0")), 0)) -> 3 | J4: відрахований наказ №17-с/к від 27.02.2026
A5: 2. | B5: Гришков Едуард Сергійович | C5: н | D5: н | E5: н | F5: н | G5: н | H5: н | I5: =IF(OR(ROUND(SUM(C5:H5)/MAX(6,COUNTIF(C5:H5, ">0")), 0) <= 1, COUNTIF(C5:H5, ">0") = 0), "н/а", ROUND(SUM(C5:H5)/MAX(6,COUNTIF(C5:H5, ">0")), 0)) -> н/а | K5: н | L5: н | M5: н | N5: н | O5: відрахований наказ №29-с/к від 27.03.26
A6: 3. | B6: Дворник Іван Миколайович | C6: 3 | D6: 4 | E6: 4 | F6: 5 | G6: н | H6: 3 | I6: =IF(OR(ROUND(SUM(C6:H6)/MAX(6,COUNTIF(C6:H6, ">0")), 0) <= 1, COUNTIF(C6:H6, ">0") = 0), "н/а", ROUND(SUM(C6:H6)/MAX(6,COUNTIF(C6:H6, ">0")), 0)) -> 3 | K6: н | L6: н | M6: н | N6: 3 | O6: 3 | P6: н | Q6: =IF(OR(ROUND(SUM(K6:P6)/MAX(5,COUNTIF(K6:P6, ">0")), 0) <= 1, COUNTIF(K6:P6, ">0") = 0), "н/а", ROUND(SUM(K6:P6)/MAX(5,COUNTIF(K6:P6, ">0")), 0)) -> н/а | R6: 3 | S6: =IF(OR(I6="н/а", R6="н/а", ROUND(SUM(I6, R6)/2, 0) <= 1), "н/а", ROUND(SUM(R6, R6)/2, 0)) -> 3 | U6: =S6 -> 3
A7: 4. | B7: Демченко Максим Сергійович | C7: н | D7: н | E7: н | F7: н | G7: відрахований наказ №15-с/к від 18.02.2026
A8: 5. | B8: Івахненко Олександр Олександрович | C8: н | D8: н | E8: н | F8: н | G8: академічна відпустка наказ №14-с/к від 16.02.26
A9: 6. | B9: Ішков Леонід Вікторович | C9: 5 | D9: 5 | E9: 4 | F9: 5 | G9: 5 | H9: 4 | I9: =IF(OR(ROUND(SUM(C9:H9)/MAX(6,COUNTIF(C9:H9, ">0")), 0) <= 1, COUNTIF(C9:H9, ">0") = 0), "н/а", ROUND(SUM(C9:H9)/MAX(6,COUNTIF(C9:H9, ">0")), 0)) -> 5 | K9: 5 | L9: 5 | M9: 5 | N9: 5 | O9: 5 | Q9: =IF(OR(ROUND(SUM(K9:P9)/MAX(5,COUNTIF(K9:P9, ">0")), 0) <= 1, COUNTIF(K9:P9, ">0") = 0), "н/а", ROUND(SUM(K9:P9)/MAX(5,COUNTIF(K9:P9, ">0")), 0)) -> 5 | S9: =IF(OR(I9="н/а", Q9="н/а", ROUND(SUM(I9, Q9)/2, 0) <= 1), "н/а", ROUND(SUM(I9, Q9)/2, 0)) -> 5 | U9: =S9 -> 5
A10: 7. | B10: Каратаєв Данііл Сергійович | C10: 3 | D10: 3 | E10: 4 | F10: 4 | G10: н | H10: 3 | I10: =IF(OR(ROUND(SUM(C10:H10)/MAX(6,COUNTIF(C10:H10, ">0")), 0) <= 1, COUNTIF(C10:H10, ">0") = 0), "н/а", ROUND(SUM(C10:H10)/MAX(6,COUNTIF(C10:H10, ">0")), 0)) -> 3 | K10: 4 | M10: 4 | N10: 2 | P10: н | Q10: =IF(OR(ROUND(SUM(K10:P10)/MAX(5,COUNTIF(K10:P10, ">0")), 0) <= 1, COUNTIF(K10:P10, ">0") = 0), "н/а", ROUND(SUM(K10:P10)/MAX(5,COUNTIF(K10:P10, ">0")), 0)) -> 2 | S10: =IF(OR(I10="н/а", Q10="н/а", ROUND(SUM(I10, Q10)/2, 0) <= 1), "н/а", ROUND(SUM(I10, Q10)/2, 0)) -> 3 | U10: =S10 -> 3
A11: 8. | B11: Кисляков Дмитро Олександрович | C11: 5 | D11: 4 | E11: 4 | F11: 4 | H11: 5 | I11: =IF(OR(ROUND(SUM(C11:H11)/MAX(6,COUNTIF(C11:H11, ">0")), 0) <= 1, COUNTIF(C11:H11, ">0") = 0), "н/а", ROUND(SUM(C11:H11)/MAX(6,COUNTIF(C11:H11, ">0")), 0)) -> 4 | K11: 4 | L11: н | M11: 5 | N11: 5 | O11: 5 | Q11: =IF(OR(ROUND(SUM(K11:P11)/MAX(5,COUNTIF(K11:P11, ">0")), 0) <= 1, COUNTIF(K11:P11, ">0") = 0), "н/а", ROUND(SUM(K11:P11)/MAX(5,COUNTIF(K11:P11, ">0")), 0)) -> 4 | S11: =IF(OR(I11="н/а", Q11="н/а", ROUND(SUM(I11, Q11)/2, 0) <= 1), "н/а", ROUND(SUM(I11, Q11)/2, 0)) -> 4 | U11: =S11 -> 4
A12: 9. | B12: Ковальчук Арсеній Борисович | C12: н | D12: н | E12: н | F12: н | G12: н | H12: н | I12: =IF(OR(ROUND(SUM(C12:H12)/MAX(6,COUNTIF(C12:H12, ">0")), 0) <= 1, COUNTIF(C12:H12, ">0") = 0), "н/а", ROUND(SUM(C12:H12)/MAX(6,COUNTIF(C12:H12, ">0")), 0)) -> н/а | J12: відрахований наказ №17-с/к від 27.02.2026
A13: 10. | B13: Кутєхов Назарій Олександрович | C13: 3 | D13: 3 | E13: 3 | F13: 3 | G13: н | H13: 3 | I13: =IF(OR(ROUND(SUM(C13:H13)/MAX(6,COUNTIF(C13:H13, ">0")), 0) <= 1, COUNTIF(C13:H13, ">0") = 0), "н/а", ROUND(SUM(C13:H13)/MAX(6,COUNTIF(C13:H13, ">0")), 0)) -> 3 | K13: н | L13: н | M13: н | N13: н | O13: н | P13: н | Q13: =IF(OR(ROUND(SUM(K13:P13)/MAX(5,COUNTIF(K13:P13, ">0")), 0) <= 1, COUNTIF(K13:P13, ">0") = 0), "н/а", ROUND(SUM(K13:P13)/MAX(5,COUNTIF(K13:P13, ">0")), 0)) -> н/а | S13: =IF(OR(I13="н/а", Q13="н/а", ROUND(SUM(I13, Q13)/2, 0) <= 1), "н/а", ROUND(SUM(I13, Q13)/2, 0)) -> н/а | U13: =S13 -> н/а
A14: 11. | B14: Малюк Нікіта Сергійович | C14: н | D14: 4 | E14: 3 | F14: 4 | G14: н | H14: 4 | I14: =IF(OR(ROUND(SUM(C14:H14)/MAX(6,COUNTIF(C14:H14, ">0")), 0) <= 1, COUNTIF(C14:H14, ">0") = 0), "н/а", ROUND(SUM(C14:H14)/MAX(6,COUNTIF(C14:H14, ">0")), 0)) -> 3 | K14: 5 | M14: н | N14: н | O14: н | P14: н | Q14: 2 | S14: =IF(OR(I14="н/а", Q14="н/а", ROUND(SUM(I14, Q14)/2, 0) <= 1), "н/а", ROUND(SUM(I14, Q14)/2, 0)) -> 3 | U14: =S14 -> 3
A15: 12. | B15: Мезенцев Кирило Анатолійович | C15: н | D15: н | E15: н | F15: н | G15: н | H15: н | I15: =IF(OR(ROUND(SUM(C15:H15)/MAX(6,COUNTIF(C15:H15, ">0")), 0) <= 1, COUNTIF(C15:H15, ">0") = 0), "н/а", ROUND(SUM(C15:H15)/MAX(6,COUNTIF(C15:H15, ">0")), 0)) -> н/а | J15: відрахований наказ №18-с/к від 04.04.26
A16: 13. | B16: Надіров Расім Аріфович | C16: н | D16: н | E16: н | F16: н | G16: н | H16: н | I16: академічна відпустка наказ №16-с/к від 25.02.26
A17: 14. | B17: Онищенко Ярослав Віталійович | C17: н | D17: н | E17: н | F17: н | G17: н | H17: н | I17: =IF(OR(ROUND(SUM(C17:H17)/MAX(6,COUNTIF(C17:H17, ">0")), 0) <= 1, COUNTIF(C17:H17, ">0") = 0), "н/а", ROUND(SUM(C17:H17)/MAX(6,COUNTIF(C17:H17, ">0")), 0)) -> н/а | J17: відрахований наказ №17-с/к від 27.02.2026
A18: 15. | B18: Павлюк Дмитро Ігорович | C18: н | D18: н | E18: н | F18: н | G18: н | H18: н | I18: =IF(OR(ROUND(SUM(C18:H18)/MAX(6,COUNTIF(C18:H18, ">0")), 0) <= 1, COUNTIF(C18:H18, ">0") = 0), "н/а", ROUND(SUM(C18:H18)/MAX(6,COUNTIF(C18:H18, ">0")), 0)) -> н/а | J18: відрахований наказ №26-с/к від 17.03.2026
A19: 16. | B19: Плетій Андрій Анатолійович | C19: н | D19: н | E19: н | F19: н | G19: н | H19: н | I19: =IF(OR(ROUND(SUM(C19:H19)/MAX(6,COUNTIF(C19:H19, ">0")), 0) <= 1, COUNTIF(C19:H19, ">0") = 0), "н/а", ROUND(SUM(C19:H19)/MAX(6,COUNTIF(C19:H19, ">0")), 0)) -> н/а | J19: відрахований наказ №18-с/к від 04.04.26
A20: 17. | B20: Портаненко Гліб Олександрович | C20: н | D20: 5 | E20: 5 | F20: 4 | G20: н | H20: 5 | I20: =IF(OR(ROUND(SUM(C20:H20)/MAX(6,COUNTIF(C20:H20, ">0")), 0) <= 1, COUNTIF(C20:H20, ">0") = 0), "н/а", ROUND(SUM(C20:H20)/MAX(6,COUNTIF(C20:H20, ">0")), 0)) -> 3 | K20: 4 | L20: н | M20: 5 | N20: 4 | O20: 4 | P20: н | Q20: =IF(OR(ROUND(SUM(K20:P20)/MAX(5,COUNTIF(K20:P20, ">0")), 0) <= 1, COUNTIF(K20:P20, ">0") = 0), "н/а", ROUND(SUM(K20:P20)/MAX(5,COUNTIF(K20:P20, ">0")), 0)) -> 3 | S20: =IF(OR(I20="н/а", Q20="н/а", ROUND(SUM(I20, Q20)/2, 0) <= 1), "н/а", ROUND(SUM(I20, Q20)/2, 0)) -> 3 | U20: =S20 -> 3
A21: 18. | B21: Ткаченко Кирило Сергійович | D21: 3 | E21: 3 | F21: 5 | G21: н | H21: 4 | I21: =IF(OR(ROUND(SUM(C21:H21)/MAX(6,COUNTIF(C21:H21, ">0")), 0) <= 1, COUNTIF(C21:H21, ">0") = 0), "н/а", ROUND(SUM(C21:H21)/MAX(6,COUNTIF(C21:H21, ">0")), 0)) -> 3 | K21: 4 | M21: н | N21: н | O21: н | P21: н | Q21: =IF(OR(ROUND(SUM(K21:P21)/MAX(5,COUNTIF(K21:P21, ">0")), 0) <= 1, COUNTIF(K21:P21, ">0") = 0), "н/а", ROUND(SUM(K21:P21)/MAX(5,COUNTIF(K21:P21, ">0")), 0)) -> н/а | R21: 3 | S21: =IF(OR(I21="н/а", Q21="н/а", ROUND(SUM(I21, Q21)/2, 0) <= 1), "н/а", ROUND(SUM(I21, Q21)/2, 0)) -> н/а | T21: 3 | U21: =S21 -> н/а | V21: 3
A22: 19. | B22: Царюк Єгор Андрійович | C22: 5 | D22: 4 | E22: 4 | F22: 3 | G22: 5 | H22: 3 | I22: =IF(OR(ROUND(SUM(C22:H22)/MAX(6,COUNTIF(C22:H22, ">0")), 0) <= 1, COUNTIF(C22:H22, ">0") = 0), "н/а", ROUND(SUM(C22:H22)/MAX(6,COUNTIF(C22:H22, ">0")), 0)) -> 4 | K22: 3 | L22: 5 | M22: 5 | O22: 4 | Q22: =IF(OR(ROUND(SUM(K22:P22)/MAX(5,COUNTIF(K22:P22, ">0")), 0) <= 1, COUNTIF(K22:P22, ">0") = 0), "н/а", ROUND(SUM(K22:P22)/MAX(5,COUNTIF(K22:P22, ">0")), 0)) -> 3 | S22: =IF(OR(I22="н/а", Q22="н/а", ROUND(SUM(I22, Q22)/2, 0) <= 1), "н/а", ROUND(SUM(I22, Q22)/2, 0)) -> 4 | U22: =S22 -> 4
A23: 20. | B23: Дорубайло Ілля Олексійович | C23: н | D23: н | E23: н | F23: н | G23: н | H23: н | I23: =IF(OR(ROUND(SUM(C23:H23)/MAX(6,COUNTIF(C23:H23, ">0")), 0) <= 1, COUNTIF(C23:H23, ">0") = 0), "н/а", ROUND(SUM(C23:H23)/MAX(6,COUNTIF(C23:H23, ">0")), 0)) -> н/а | K23: н | L23: н | M23: н | N23: н | O23: н | P23: н | Q23: =IF(OR(ROUND(SUM(K23:P23)/MAX(5,COUNTIF(K23:P23, ">0")), 0) <= 1, COUNTIF(K23:P23, ">0") = 0), "н/а", ROUND(SUM(K23:P23)/MAX(5,COUNTIF(K23:P23, ">0")), 0)) -> н/а | S23: =IF(OR(I23="н/а", Q23="н/а", ROUND(SUM(I23, Q23)/2, 0) <= 1), "н/а", ROUND(SUM(I23, Q23)/2, 0)) -> н/а | U23: =S23 -> н/а
C24: дз | D24: тест | E24: тест | F24: тест | G24: пр1 | H24: тест | K24: тест | L24: пр2 | M24: тест | N24: тест | O24: тест
A25: № | B25: Дата | C25: Години | D25: яч | M25: Домашня робота
A26: 1 | B26: 46080 | C26: 2 | D26: Тема 1.1. Концепція захисту інформації та інформаційних технологій. Концепція захисту інформації та інформаційних технологій. Категорії комп’ютерної безпеки | M26: Домашня робота в classroom
A27: 2 | B27: 46056 | C27: 2 | D27: Правове регулювання обігу та захисту інформації | M27: Тест в classroom
A28: 3 | B28: 46063 | C28: 2 | D28: Основні види загроз конфіденційності інформації | M28: Тест в classroom
A29: 4 | B29: 46070 | C29: 2 | D29: Тема 1.2 Основні методи захисту ПЗ Основні методи захисту ПЗ: від вірусів, від незадекларованих можливостей ПЗ (закладок) | M29: Тест в classroom
A30: 5 | B30: 46077 | C30: 2 | D30: ПР №1. Вивчення перших методів шифрування інформації | M30: Практична №1
A31: 6 | B31: 46084 | C31: 2 | D31: ПР №2. Огляд складових інформаційної безпеки | M31: Тест в classroom
A32: 7 | B32: 46091 | C32: 2 | D32: Розділ ІІ. Комплексна система захисту інформації Тема 1.3 Організація системи захисту інформації | M32: Тест в classroom
A33: 8 | B33: 46098 | C33: 2 | D33: Організація системи захисту інформації. Політика безпеки | M33: Практична №2
A34: 9 | B34: 46105 | C34: 2 | D34: ПР №3. Використання кейлогерів для збереження інформації. | M34: Тест в classroom
A35: 10 | B35: 46112 | C35: 2 | D35: ПР №4. Генерування і використання електронного цифрового підпису для реалізації захисту файлів користувача. | M35: Тест в classroom
A36: 11 | B36: 46119 | C36: 2 | D36: Захист інформації шляхом перетворення. Криптографічні вимоги до захисту інформації | M36: Тест в classroom
A37: 12 | B37: 46126 | C37: 2 | D37: Робота з криптографічними засобами шифрування інформації

Sheet Компютерна логіка
B1: Назва дисципліни | C1: Комп'ютерна логіка (КМ-42)
B2: Викладач | C2: Науменко П.В.
A3: № | B3: ПІБ студента | C3: 45943 | D3: 45945 | E3: 45947 | F3: 45948 | G3: 45950 | H3: 45952 | I3: 45954 | J3: 45957 | K3: Тематична | M3: 45959 | N3: 45961 | O3: 45964 | P3: 45966 | Q3: 45968 | R3: 45971 | S3: 45973 | T3: 45975 | U3: Тематична | W3: 45976 | X3: 45978 | Y3: 45980 | Z3: 45982 | AA3: 45985 | AB3: 45987 | AC3: 45989 | AD3: 45992 | AE3: Тематична | AG3: 45994 | AH3: 45996 | AI3: 45999 | AJ3: 46001 | AK3: 46003 | AL3: 46004 | AM3: 46006 | AN3: 46008 | AO3: 46009 | AP3: 46010 | AQ3: Тематична | AS3: Семестрова | AU3: Екзамен
A4: 1. | B4: Гриценко Денис Сергійович | C4: н | D4: 2 | E4: н | F4: н | G4: н | H4: н | I4: 2 | J4: н | K4: н/а | M4: н | N4: н | O4: 2 | P4: н | Q4: н | R4: н | S4: н | T4: н | U4: н/а | W4: н | X4: н | Y4: н | Z4: н | AA4: н | AB4: н | AC4: н | AD4: н | AE4: н/а | AG4: н | AH4: н | AI4: н | AJ4: н | AK4: н | AL4: н | AM4: н | AN4: н | AO4: н | AP4: н | AQ4: н/а | AS4: н/а | AU4: н/д | AV4: відрахований наказ №17-с/к від 27.02.2026
A5: 2. | B5: Гришков Едуард Сергійович | C5: н | D5: н | E5: н | F5: н | G5: н | H5: н | I5: н | J5: н | K5: н/а | M5: н | N5: н | O5: н | P5: н | Q5: н | R5: н | S5: н | T5: н | U5: н/а | W5: н | X5: н | Y5: н | Z5: н | AA5: н | AB5: н | AC5: н | AD5: н | AE5: н/а | AG5: н | AH5: н | AI5: н | AJ5: н | AK5: н | AL5: н | AM5: н | AN5: н | AO5: н | AP5: н | AQ5: н/а | AS5: н/а | AU5: н/д | AV5: відрахований наказ №29-с/к від 27.03.26
A6: 3. | B6: Дворник Іван Миколайович | D6: 5 | F6: н | G6: 3 | H6: н | I6: 5 | K6: 4 | M6: н | N6: н | O6: 5 | P6: н | Q6: 3 | R6: н | S6: н | T6: н | U6: 4 | W6: н | Y6: н | AA6: н | AB6: н | AC6: н | AE6: н/а | AF6: 3 | AG6: н | AI6: н | AK6: 5 | AL6: н | AM6: 3 | AN6: 5 | AO6: 5 | AP6: н | AQ6: 5 | AS6: 4 | AU6: 4
A7: 4. | B7: Демченко Максим Сергійович | C7: н | D7: н | E7: н | F7: н | G7: н | H7: н | I7: н | J7: н | K7: н/а | M7: н | N7: н | O7: н | P7: н | Q7: н | R7: н | S7: н | T7: н | U7: н/а | W7: н | X7: н | Y7: н | Z7: н | AA7: н | AB7: н | AC7: н | AD7: н | AE7: н/а | AG7: н | AH7: н | AI7: н | AJ7: н | AK7: н | AL7: н | AM7: н | AN7: н | AO7: н | AP7: н | AQ7: н/а | AS7: н/а | AU7: н/д | AV7: відрахований наказ №15-с/к від 18.02.2026
A8: 5. | B8: Івахненко Олександр Олександрович | C8: н | D8: н | E8: н | F8: н | G8: н | H8: н | I8: н | J8: н | K8: н/а | M8: н | N8: н | O8: н | P8: н | Q8: н | R8: н | S8: н | T8: н | U8: н/а | W8: н | X8: н | Y8: н | Z8: н | AA8: н | AB8: н | AC8: н | AD8: н | AE8: н/а | AG8: н | AH8: н | AI8: н | AJ8: н | AK8: н | AL8: н | AM8: н | AN8: н | AO8: н | AP8: н | AQ8: н/а | AS8: н/а | AU8: н/д | AV8: академічна відпустка наказ №14-с/к від 16.02.26
A9: 6. | B9: Ішков Леонід Вікторович | D9: 5 | G9: 5 | I9: 5 | K9: 5 | M9: 5 | O9: 5 | Q9: 5 | S9: 5 | U9: 5 | W9: 5 | AA9: 5 | AB9: 5 | AE9: 5 | AG9: 5 | AK9: 5 | AM9: 5 | AN9: 5 | AO9: 5 | AQ9: 5 | AS9: 5 | AU9: 5
A10: 7. | B10: Каратаєв Данііл Сергійович | D10: н | E10: 4 | F10: н | G10: 3 | H10: 5 | I10: н | J10: н | K10: 4 | M10: 4 | N10: 4 | O10: 5 | P10: н | Q10: 2 | R10: н | S10: 5 | T10: н | U10: 4 | W10: н | X10: н | AA10: 3 | AB10: 2 | AE10: 3 | AG10: 2 | AK10: н | AM10: 5 | AN10: 5 | AO10: 5 | AQ10: 4 | AS10: 4 | AU10: 4
A11: 8. | B11: Кисляков Дмитро Олександрович | D11: 5 | E11: н | F11: н | G11: н | H11: н | I11: 2 | J11: 2 | K11: 3 | M11: 5 | O11: н | Q11: 5 | R11: н | S11: н | T11: 5 | U11: 5 | W11: 3 | Y11: н | AA11: н | AB11: 5 | AD11: 5 | AE11: 4 | AG11: 2 | AK11: 5 | AM11: н | AN11: 5 | AO11: 5 | AQ11: 4 | AS11: 4 | AU11: 4
A12: 9. | B12: Ковальчук Арсеній Борисович | C12: н | D12: н | E12: н | F12: н | G12: н | H12: н | I12: н | J12: н | K12: н/а | M12: н | N12: н | O12: н | P12: н | Q12: н | R12: н | S12: н | T12: н | U12: н/а | W12: н | X12: н | Y12: н | Z12: н | AA12: н | AB12: н | AC12: н | AD12: н | AE12: н/а | AG12: н | AH12: н | AI12: н | AJ12: н | AK12: н | AL12: н | AM12: н | AN12: н | AO12: н | AP12: н | AQ12: н/а | AS12: н/а | AU12: н/д | AV12: відрахований наказ №17-с/к від 27.02.2026
A13: 10. | B13: Кутєхов Назарій Олександрович | C13: н | D13: н | E13: н | F13: н | G13: н | H13: н | I13: н | J13: н | K13: н/а | L13: 3 | M13: н | N13: н | O13: н | P13: н | Q13: н | R13: н | S13: н | T13: н | U13: н/а | V13: 3 | W13: н | X13: н | Y13: н | Z13: н | AA13: н | AB13: н | AC13: н | AD13: н | AE13: н/а | AF13: 3 | AG13: н | AH13: н | AI13: н | AJ13: н | AK13: н | AL13: н | AM13: н | AN13: н | AO13: н | AP13: н | AQ13: н/а | AS13: н/а | AT13: 3 | AU13: н/д | AV13: 3
A14: 11. | B14: Малюк Нікіта Сергійович | C14: н | D14: н | E14: н | F14: н | G14: 2 | H14: 4 | I14: 4 | J14: н | K14: 3 | N14: н | O14: 4 | P14: н | Q14: 4 | R14: н | S14: н | T14: н | U14: 4 | W14: н | X14: н | Y14: н | Z14: н | AB14: н | AC14: н | AE14: н/а | AF14: 3 | AG14: 5 | AK14: н | AL14: н | AM14: 2 | AN14: 5 | AO14: 2 | AQ14: 3 | AS14: 3 | AU14: 3
A15: 12. | B15: Мезенцев Кирило Анатолійович | C15: н | D15: н | E15: н | F15: н | G15: н | H15: н | I15: н | J15: н | K15: н/а | M15: н | N15: н | O15: н | P15: н | Q15: н | R15: н | S15: н | T15: н | U15: н/а | W15: н | X15: н | Y15: н | Z15: н | AA15: н | AB15: н | AC15: н | AD15: н | AE15: н/а | AG15: н | AH15: н | AI15: н | AJ15: н | AK15: н | AL15: н | AM15: н | AN15: н | AO15: н | AP15: н | AQ15: н/а | AS15: н/а | AU15: н/д | AV15: відрахований наказ №18-с/к від 04.04.26
A16: 13. | B16: Надіров Расім Аріфович | C16: н | D16: н | E16: н | F16: н | G16: н | H16: н | I16: н | J16: н | K16: н/а | M16: н | N16: н | O16: н | P16: н | Q16: н | R16: н | S16: н | T16: н | U16: н/а | W16: н | X16: н | Y16: н | Z16: н | AA16: н | AB16: н | AC16: н | AD16: н | AE16: н/а | AG16: н | AH16: н | AI16: н | AJ16: н | AK16: н | AL16: н | AM16: н | AN16: н | AO16: н | AP16: н | AQ16: н/а | AS16: н/а | AU16: н/д | AV16: академічна відпустка наказ №16-с/к від 25.02.26
